<mujoco model="berkeley-humanoid-lite">
  <compiler angle="radian" meshdir="../meshes/"/>

  <asset>
    <mesh name="base_visual" file="base_visual.stl"/>
    <mesh name="imu_visual" file="imu_visual.stl"/>
    <mesh name="leg_left_hip_roll_visual" file="leg_left_hip_roll_visual.stl"/>
    <mesh name="leg_left_hip_yaw_visual" file="leg_left_hip_yaw_visual.stl"/>
    <mesh name="leg_left_hip_pitch_visual" file="leg_left_hip_pitch_visual.stl"/>
    <mesh name="leg_left_knee_pitch_visual" file="leg_left_knee_pitch_visual.stl"/>
    <mesh name="leg_left_ankle_pitch_visual" file="leg_left_ankle_pitch_visual.stl"/>
    <mesh name="leg_left_ankle_roll_visual" file="leg_left_ankle_roll_visual.stl"/>
    <mesh name="leg_right_hip_roll_visual" file="leg_right_hip_roll_visual.stl"/>
    <mesh name="leg_right_hip_yaw_visual" file="leg_right_hip_yaw_visual.stl"/>
    <mesh name="leg_right_hip_pitch_visual" file="leg_right_hip_pitch_visual.stl"/>
    <mesh name="leg_right_knee_pitch_visual" file="leg_right_knee_pitch_visual.stl"/>
    <mesh name="leg_right_ankle_pitch_visual" file="leg_right_ankle_pitch_visual.stl"/>
    <mesh name="leg_right_ankle_roll_visual" file="leg_right_ankle_roll_visual.stl"/>
  </asset>

  <worldbody>
    <body name="base" pos="0 0 0.65">
      <freejoint/>
      <site name="imu" size="0.01" pos="0 0 0" />
      <geom size="0.075 0.07 0.115" pos="0 0 0.11" quat="0.707105 0 0 -0.707108" type="box"/>
      <geom type="mesh" contype="0" conaffinity="0" group="1" density="0" rgba="0.8 0.8 0.8 1" mesh="base_visual"/>
      <geom pos="0.061722 0 0.08" quat="1 0 0 0" type="mesh" contype="0" conaffinity="0" group="1" density="0" rgba="0.8 0.8 0.8 1" mesh="imu_visual"/>
      <body name="leg_left_hip_roll" pos="-0.0290919 0.08 -0.057369" quat="0.92388 0 0.382683 0">
        <inertial pos="-0.00410941 -0.000112596 -0.0464623" quat="0.998579 -0.0134956 0.0323242 0.0401687" mass="0.83786" diaginertia="0.00098151 0.00089565 0.000726479"/>
        <joint name="leg_left_hip_roll_joint" pos="0 0 0" axis="0 0 1" range="-0.174533 1.5708" actuatorfrcrange="-20 20" armature="0.007" frictionloss="0.1"/>
        <geom type="mesh" contype="0" conaffinity="0" group="1" density="0" rgba="0.8 0.8 0.8 1" mesh="leg_left_hip_roll_visual"/>
        <body name="leg_left_hip_yaw" pos="0.027 0 -0.052" quat="0.499998 -0.5 0.500002 -0.5">
          <inertial pos="-0.00411632 -8.63203e-05 0.0463382" quat="0.999084 -0.0161651 -0.0382793 -0.010234" mass="0.837683" diaginertia="0.000980566 0.000898328 0.00072259"/>
          <joint name="leg_left_hip_yaw_joint" pos="0 0 0" axis="0 0 1" range="-0.981748 0.589049" actuatorfrcrange="-20 20" armature="0.007" frictionloss="0.1"/>
          <geom type="mesh" contype="0" conaffinity="0" group="1" density="0" rgba="0.8 0.8 0.8 1" mesh="leg_left_hip_yaw_visual"/>
          <body name="leg_left_hip_pitch" pos="0.027 0 0.052" quat="0.65328 0.270598 -0.653282 -0.270598">
            <inertial pos="0.0030405 0.120388 0.0210924" quat="0.761917 0.646837 0.0270389 0.0188058" mass="0.947974" diaginertia="0.00287266 0.00264321 0.000972851"/>
            <joint name="leg_left_hip_pitch_joint" pos="0 0 0" axis="0 0 1" range="-1.89805 0.981748" actuatorfrcrange="-20 20" armature="0.007" frictionloss="0.1"/>
            <geom size="0.05 0.065" pos="0.00597627 0.039 0.0295" quat="0.499998 0.5 0.5 -0.500002" type="cylinder"/>
            <geom type="mesh" contype="0" conaffinity="0" group="1" density="0" rgba="0.8 0.8 0.8 1" mesh="leg_left_hip_pitch_visual"/>
            <body name="leg_left_knee_pitch" pos="0 0.15 -0.018" quat="1.32679e-06 0 0 -1">
              <inertial pos="-4.14041e-05 -0.112249 0.0257397" quat="0.716105 0.697988 -0.00189175 0.00175183" mass="0.653864" diaginertia="0.00230127 0.00203823 0.000558782"/>
              <joint name="leg_left_knee_pitch_joint" pos="0 0 0" axis="0 0 1" range="0 2.44346" actuatorfrcrange="-20 20" armature="0.007" frictionloss="0.1"/>
              <geom size="0.04 0.075" pos="0 -0.115 0.022" quat="0.499998 -0.5 0.5 0.500002" type="cylinder"/>
              <geom type="mesh" contype="0" conaffinity="0" group="1" density="0" rgba="0.8 0.8 0.8 1" mesh="leg_left_knee_pitch_visual"/>
              <body name="leg_left_ankle_pitch" pos="0 -0.16 -0.003" quat="1.32679e-06 0 0 -1">
                <inertial pos="0.0131065 0.0273743 0.0274153" quat="0.97446 -0.0895638 0.0341084 -0.203084" mass="0.106196" diaginertia="0.000199494 0.000133736 7.96933e-05"/>
                <joint name="leg_left_ankle_pitch_joint" pos="0 0 0" axis="0 0 1" range="-0.785398 0.785398" actuatorfrcrange="-20 20" armature="0.002" frictionloss="0.1"/>
                <geom type="mesh" contype="0" conaffinity="0" group="1" density="0" rgba="0.8 0.8 0.8 1" mesh="leg_left_ankle_pitch_visual"/>
                <body name="leg_left_ankle_roll" pos="0.03 0.05 0.025" quat="0.707105 0 0.707108 0">
                  <inertial pos="2.41275e-05 0.0238403 0.020082" quat="0.998464 0.0551979 5.50639e-05 0.00477372" mass="0.671532" diaginertia="0.0019476 0.00189924 0.000548971"/>
                  <joint name="leg_left_ankle_roll_joint" pos="0 0 0" axis="0 0 1" range="-0.261799 0.261799" actuatorfrcrange="-20 20" armature="0.002" frictionloss="0.1"/>
                  <geom size="0.036 0.11 0.02" pos="0 0.03 0.006" quat="0.707105 0.707108 0 0" type="box"/>
                  <geom type="mesh" contype="0" conaffinity="0" group="1" density="0" rgba="0.8 0.8 0.8 1" mesh="leg_left_ankle_roll_visual"/>
                </body>
              </body>
            </body>
          </body>
        </body>
      </body>
      <body name="leg_right_hip_roll" pos="-0.0290919 -0.08 -0.057369" quat="1.2258e-06 0.382683 -5.07742e-07 0.92388">
        <inertial pos="0.00410941 -0.00018505 -0.0464478" quat="0.99915 -0.0125114 -0.0311449 -0.0239221" mass="0.83786" diaginertia="0.000980934 0.000896266 0.000726135"/>
        <joint name="leg_right_hip_roll_joint" pos="0 0 0" axis="0 0 1" range="-1.5708 0.174533" actuatorfrcrange="-20 20" armature="0.007" frictionloss="0.1"/>
        <geom type="mesh" contype="0" conaffinity="0" group="1" density="0" rgba="0.8 0.8 0.8 1" mesh="leg_right_hip_roll_visual"/>
        <body name="leg_right_hip_yaw" pos="-0.027 0 -0.052" quat="0.499998 -0.5 -0.500002 0.5">
          <inertial pos="0.00411632 -1.3851e-05 0.0463238" quat="0.999168 -0.0154252 0.0370844 -0.00703098" mass="0.837683" diaginertia="0.00098034 0.000898597 0.000722286"/>
          <joint name="leg_right_hip_yaw_joint" pos="0 0 0" axis="0 0 1" range="-0.589049 0.981748" actuatorfrcrange="-20 20" armature="0.007" frictionloss="0.1"/>
          <geom type="mesh" contype="0" conaffinity="0" group="1" density="0" rgba="0.8 0.8 0.8 1" mesh="leg_right_hip_yaw_visual"/>
          <body name="leg_right_hip_pitch" pos="-0.027 0 0.052" quat="0.65328 0.270598 -0.653282 -0.270598">
            <inertial pos="0.00319928 0.120388 -0.0210924" quat="0.646378 0.762188 0.00805307 0.0346537" mass="0.947974" diaginertia="0.00287232 0.00264204 0.000972473"/>
            <joint name="leg_right_hip_pitch_joint" pos="0 0 0" axis="0 0 1" range="-1.89805 0.981748" actuatorfrcrange="-20 20" armature="0.007" frictionloss="0.1"/>
            <geom size="0.05 0.065" pos="0.00597627 0.039 -0.0295" quat="0.499998 0.5 0.5 -0.500002" type="cylinder"/>
            <geom type="mesh" contype="0" conaffinity="0" group="1" density="0" rgba="0.8 0.8 0.8 1" mesh="leg_right_hip_pitch_visual"/>
            <body name="leg_right_knee_pitch" pos="0 0.15 0.018">
              <inertial pos="-5.09429e-05 0.112249 -0.0257397" quat="0.716106 0.697988 0.00180037 -0.00128014" mass="0.653864" diaginertia="0.00230127 0.00203824 0.00055878"/>
              <joint name="leg_right_knee_pitch_joint" pos="0 0 0" axis="0 0 1" range="0 2.44346" actuatorfrcrange="-20 20" armature="0.007" frictionloss="0.1"/>
              <geom size="0.04 0.075" pos="0 0.115 -0.022" quat="0.499998 0.5 0.5 -0.500002" type="cylinder"/>
              <geom type="mesh" contype="0" conaffinity="0" group="1" density="0" rgba="0.8 0.8 0.8 1" mesh="leg_right_knee_pitch_visual"/>
              <body name="leg_right_ankle_pitch" pos="0 0.16 0.003">
                <inertial pos="0.0131065 0.0273743 -0.0274153" quat="0.97446 0.0895638 -0.0341084 -0.203084" mass="0.106196" diaginertia="0.000199494 0.000133736 7.96934e-05"/>
                <joint name="leg_right_ankle_pitch_joint" pos="0 0 0" axis="0 0 1" range="-0.785398 0.785398" actuatorfrcrange="-20 20" armature="0.002" frictionloss="0.1"/>
                <geom type="mesh" contype="0" conaffinity="0" group="1" density="0" rgba="0.8 0.8 0.8 1" mesh="leg_right_ankle_pitch_visual"/>
                <body name="leg_right_ankle_roll" pos="0.03 0.05 -0.025" quat="0.707105 0 0.707108 0">
                  <inertial pos="2.41275e-05 0.0238403 0.020082" quat="0.998464 0.0551979 5.50639e-05 0.00477372" mass="0.671532" diaginertia="0.0019476 0.00189924 0.000548971"/>
                  <joint name="leg_right_ankle_roll_joint" pos="0 0 0" axis="0 0 1" range="-0.261799 0.261799" actuatorfrcrange="-20 20" armature="0.002" frictionloss="0.1"/>
                  <geom size="0.036 0.11 0.02" pos="0 0.03 0.006" quat="0.707105 0.707108 0 0" type="box"/>
                  <geom type="mesh" contype="0" conaffinity="0" group="1" density="0" rgba="0.8 0.8 0.8 1" mesh="leg_right_ankle_roll_visual"/>
                </body>
              </body>
            </body>
          </body>
        </body>
      </body>
    </body>
  </worldbody>

  <actuator>
    <motor name="leg_left_hip_roll"     gear="1" joint="leg_left_hip_roll_joint"/>
    <motor name="leg_left_hip_yaw"      gear="1" joint="leg_left_hip_yaw_joint"/>
    <motor name="leg_left_hip_pitch"    gear="1" joint="leg_left_hip_pitch_joint"/>
    <motor name="leg_left_knee_pitch"   gear="1" joint="leg_left_knee_pitch_joint"/>
    <motor name="leg_left_ankle_pitch"  gear="1" joint="leg_left_ankle_pitch_joint"/>
    <motor name="leg_left_ankle_roll"   gear="1" joint="leg_left_ankle_roll_joint"/>
    <motor name="leg_right_hip_roll"    gear="1" joint="leg_right_hip_roll_joint"/>
    <motor name="leg_right_hip_yaw"     gear="1" joint="leg_right_hip_yaw_joint"/>
    <motor name="leg_right_hip_pitch"   gear="1" joint="leg_right_hip_pitch_joint"/>
    <motor name="leg_right_knee_pitch"  gear="1" joint="leg_right_knee_pitch_joint"/>
    <motor name="leg_right_ankle_pitch" gear="1" joint="leg_right_ankle_pitch_joint"/>
    <motor name="leg_right_ankle_roll"  gear="1" joint="leg_right_ankle_roll_joint"/>
  </actuator>

  <sensor>
    <jointpos name="leg_left_hip_roll_pos"      joint="leg_left_hip_roll_joint"/>
    <jointpos name="leg_left_hip_yaw_pos"       joint="leg_left_hip_yaw_joint"/>
    <jointpos name="leg_left_hip_pitch_pos"     joint="leg_left_hip_pitch_joint"/>
    <jointpos name="leg_left_knee_pitch_pos"    joint="leg_left_knee_pitch_joint"/>
    <jointpos name="leg_left_ankle_pitch_pos"   joint="leg_left_ankle_pitch_joint"/>
    <jointpos name="leg_left_ankle_roll_pos"    joint="leg_left_ankle_roll_joint"/>
    <jointpos name="leg_right_hip_roll_pos"     joint="leg_right_hip_roll_joint"/>
    <jointpos name="leg_right_hip_yaw_pos"      joint="leg_right_hip_yaw_joint"/>
    <jointpos name="leg_right_hip_pitch_pos"    joint="leg_right_hip_pitch_joint"/>
    <jointpos name="leg_right_knee_pitch_pos"   joint="leg_right_knee_pitch_joint"/>
    <jointpos name="leg_right_ankle_pitch_pos"  joint="leg_right_ankle_pitch_joint"/>
    <jointpos name="leg_right_ankle_roll_pos"   joint="leg_right_ankle_roll_joint"/>

    <jointvel name="leg_left_hip_roll_vel"      joint="leg_left_hip_roll_joint"/>
    <jointvel name="leg_left_hip_yaw_vel"       joint="leg_left_hip_yaw_joint"/>
    <jointvel name="leg_left_hip_pitch_vel"     joint="leg_left_hip_pitch_joint"/>
    <jointvel name="leg_left_knee_pitch_vel"    joint="leg_left_knee_pitch_joint"/>
    <jointvel name="leg_left_ankle_pitch_vel"   joint="leg_left_ankle_pitch_joint"/>
    <jointvel name="leg_left_ankle_roll_vel"    joint="leg_left_ankle_roll_joint"/>
    <jointvel name="leg_right_hip_roll_vel"     joint="leg_right_hip_roll_joint"/>
    <jointvel name="leg_right_hip_yaw_vel"      joint="leg_right_hip_yaw_joint"/>
    <jointvel name="leg_right_hip_pitch_vel"    joint="leg_right_hip_pitch_joint"/>
    <jointvel name="leg_right_knee_pitch_vel"   joint="leg_right_knee_pitch_joint"/>
    <jointvel name="leg_right_ankle_pitch_vel"  joint="leg_right_ankle_pitch_joint"/>
    <jointvel name="leg_right_ankle_roll_vel"   joint="leg_right_ankle_roll_joint"/>

    <jointactuatorfrc name="leg_left_hip_roll_torque"     joint="leg_left_hip_roll_joint"/>
    <jointactuatorfrc name="leg_left_hip_yaw_torque"      joint="leg_left_hip_yaw_joint"/>
    <jointactuatorfrc name="leg_left_hip_pitch_torque"    joint="leg_left_hip_pitch_joint"/>
    <jointactuatorfrc name="leg_left_knee_pitch_torque"   joint="leg_left_knee_pitch_joint"/>
    <jointactuatorfrc name="leg_left_ankle_pitch_torque"  joint="leg_left_ankle_pitch_joint"/>
    <jointactuatorfrc name="leg_left_ankle_roll_torque"   joint="leg_left_ankle_roll_joint"/>
    <jointactuatorfrc name="leg_right_hip_roll_torque"    joint="leg_right_hip_roll_joint"/>
    <jointactuatorfrc name="leg_right_hip_yaw_torque"     joint="leg_right_hip_yaw_joint"/>
    <jointactuatorfrc name="leg_right_hip_pitch_torque"   joint="leg_right_hip_pitch_joint"/>
    <jointactuatorfrc name="leg_right_knee_pitch_torque"  joint="leg_right_knee_pitch_joint"/>
    <jointactuatorfrc name="leg_right_ankle_pitch_torque" joint="leg_right_ankle_pitch_joint"/>
    <jointactuatorfrc name="leg_right_ankle_roll_torque"  joint="leg_right_ankle_roll_joint"/>

    <framequat name="imu_quat" objtype="site" objname="imu" />
    <gyro name="imu_gyro" site="imu" />
    <accelerometer name="imu_acc" site="imu" />
    <framepos name="frame_pos" objtype="site" objname="imu" />
    <framelinvel name="frame_vel" objtype="site" objname="imu" />
  </sensor>
</mujoco>
