<mujoco model="berkeley-humanoid-lite">
  <compiler angle="radian" meshdir="../meshes/"/>

  <asset>
    <mesh name="base_visual" file="base_visual.stl"/>
    <mesh name="imu_visual" file="imu_visual.stl"/>
    <mesh name="arm_left_shoulder_pitch_visual" file="arm_left_shoulder_pitch_visual.stl"/>
    <mesh name="arm_left_shoulder_roll_visual" file="arm_left_shoulder_roll_visual.stl"/>
    <mesh name="arm_left_shoulder_yaw_visual" file="arm_left_shoulder_yaw_visual.stl"/>
    <mesh name="arm_left_elbow_pitch_visual" file="arm_left_elbow_pitch_visual.stl"/>
    <mesh name="arm_left_elbow_roll_visual" file="arm_left_elbow_roll_visual.stl"/>
    <mesh name="arm_left_hand_link_visual" file="arm_left_hand_link_visual.stl"/>
    <mesh name="arm_right_shoulder_pitch_visual" file="arm_right_shoulder_pitch_visual.stl"/>
    <mesh name="arm_right_shoulder_roll_visual" file="arm_right_shoulder_roll_visual.stl"/>
    <mesh name="arm_right_shoulder_yaw_visual" file="arm_right_shoulder_yaw_visual.stl"/>
    <mesh name="arm_right_elbow_pitch_visual" file="arm_right_elbow_pitch_visual.stl"/>
    <mesh name="arm_right_elbow_roll_visual" file="arm_right_elbow_roll_visual.stl"/>
    <mesh name="arm_right_hand_link_visual" file="arm_right_hand_link_visual.stl"/>
    <mesh name="leg_left_hip_roll_visual" file="leg_left_hip_roll_visual.stl"/>
    <mesh name="leg_left_hip_yaw_visual" file="leg_left_hip_yaw_visual.stl"/>
    <mesh name="leg_left_hip_pitch_visual" file="leg_left_hip_pitch_visual.stl"/>
    <mesh name="leg_left_knee_pitch_visual" file="leg_left_knee_pitch_visual.stl"/>
    <mesh name="leg_left_ankle_pitch_visual" file="leg_left_ankle_pitch_visual.stl"/>
    <mesh name="leg_left_ankle_roll_visual" file="leg_left_ankle_roll_visual.stl"/>
    <mesh name="leg_right_hip_roll_visual" file="leg_right_hip_roll_visual.stl"/>
    <mesh name="leg_right_hip_yaw_visual" file="leg_right_hip_yaw_visual.stl"/>
    <mesh name="leg_right_hip_pitch_visual" file="leg_right_hip_pitch_visual.stl"/>
    <mesh name="leg_right_knee_pitch_visual" file="leg_right_knee_pitch_visual.stl"/>
    <mesh name="leg_right_ankle_pitch_visual" file="leg_right_ankle_pitch_visual.stl"/>
    <mesh name="leg_right_ankle_roll_visual" file="leg_right_ankle_roll_visual.stl"/>
  </asset>

  <worldbody>
    <body name="base" pos="0 0 0.65">
      <freejoint/>
      <site name="imu" size="0.01" pos="0 0 0" />
      <geom size="0.075 0.07 0.115" pos="0 0 0.11" quat="0.707105 0 0 -0.707108" type="box"/>
      <geom type="mesh" contype="0" conaffinity="0" group="1" density="0" rgba="0.8 0.8 0.8 1" mesh="base_visual"/>
      <geom pos="0.061722 0 0.08" quat="1 0 0 0" type="mesh" contype="0" conaffinity="0" group="1" density="0" rgba="0.8 0.8 0.8 1" mesh="imu_visual"/>
      <body name="arm_left_shoulder_pitch" pos="0 0.133 0.164028" quat="0.707105 -0.707108 0 0">
        <inertial pos="-0.00661228 -8.80749e-05 0.0396144" quat="0.319679 0.617338 0.645584 0.316102" mass="0.342876" diaginertia="0.000260374 0.000232404 0.000210461"/>
        <joint name="arm_left_shoulder_pitch_joint" pos="0 0 0" axis="0 0 1" range="-1.5708 0.785398" actuatorfrcrange="-20 20"/>
        <geom type="mesh" contype="0" conaffinity="0" group="1" density="0" rgba="0.8 0.8 0.8 1" mesh="arm_left_shoulder_pitch_visual"/>
        <body name="arm_left_shoulder_roll" pos="0.0255 0 0.043" quat="0.701057 0.0922949 0.701058 0.0922949">
          <inertial pos="-4.27603e-05 0.0715053 -0.0278824" quat="0.681009 0.732275 -0.000118334 -0.000705712" mass="0.416078" diaginertia="0.000651025 0.000522347 0.000336008"/>
          <joint name="arm_left_shoulder_roll_joint" pos="0 0 0" axis="0 0 1" range="-1.5708 0" actuatorfrcrange="-20 20"/>
          <geom type="mesh" contype="0" conaffinity="0" group="1" density="0" rgba="0.8 0.8 0.8 1" mesh="arm_left_shoulder_roll_visual"/>
          <body name="arm_left_shoulder_yaw" pos="0 0.123 -0.0255" quat="0.707105 -0.707108 0 0">
            <inertial pos="-0.00781722 -9.17114e-05 0.0409759" quat="0.404492 0.566646 0.595632 0.40065" mass="0.329199" diaginertia="0.000241605 0.000217901 0.000193028"/>
            <joint name="arm_left_shoulder_yaw_joint" pos="0 0 0" axis="0 0 1" range="-0.785398 0.785398" actuatorfrcrange="-20 20"/>
            <geom size="0.04 0.075" pos="0 0 -0.035" quat="1.76038e-12 -1.32679e-06 -1 1.32679e-06" type="cylinder"/>
            <geom type="mesh" contype="0" conaffinity="0" group="1" density="0" rgba="0.8 0.8 0.8 1" mesh="arm_left_shoulder_yaw_visual"/>
            <body name="arm_left_elbow_pitch" pos="0.0245 0 0.043" quat="0.499998 0.5 0.500002 0.5">
              <inertial pos="-4.27603e-05 0.0715053 -0.0278824" quat="0.681009 0.732275 -0.000118334 -0.000705712" mass="0.416078" diaginertia="0.000651025 0.000522347 0.000336008"/>
              <joint name="arm_left_elbow_pitch_joint" pos="0 0 0" axis="0 0 1" range="0 1.5708" actuatorfrcrange="-20 20"/>
              <geom type="mesh" contype="0" conaffinity="0" group="1" density="0" rgba="0.8 0.8 0.8 1" mesh="arm_left_elbow_pitch_visual"/>
              <body name="arm_left_elbow_roll" pos="0 0.123 -0.0255" quat="0.707105 -0.707108 0 0">
                <inertial pos="-0.0134596 0.00247969 0.0539929" quat="0.743582 0.0884802 0.103431 0.654644" mass="0.292567" diaginertia="0.00055922 0.000523904 0.000133438"/>
                <joint name="arm_left_elbow_roll_joint" pos="0 0 0" axis="0 0 1" range="-0.785398 0.785398" actuatorfrcrange="-20 20"/>
                <geom size="0.03 0.06" pos="0 0 -0.01" quat="1.32679e-06 1 0 0" type="cylinder"/>
                <geom type="mesh" contype="0" conaffinity="0" group="1" density="0" rgba="0.8 0.8 0.8 1" mesh="arm_left_elbow_roll_visual"/>
                <geom quat="9.38184e-07 0.707105 -0.707108 -9.38187e-07" type="mesh" contype="0" conaffinity="0" group="1" density="0" rgba="0.8 0.8 0.8 1" mesh="arm_left_hand_link_visual"/>
              </body>
            </body>
          </body>
        </body>
      </body>
      <body name="arm_right_shoulder_pitch" pos="0 -0.133 0.164028" quat="9.38184e-07 -9.38187e-07 0.707108 -0.707105">
        <inertial pos="0.00661228 -1.57066e-05 0.0397088" quat="0.632957 0.316625 0.306327 0.636614" mass="0.342876" diaginertia="0.00026055 0.000233749 0.000209377"/>
        <joint name="arm_right_shoulder_pitch_joint" pos="0 0 0" axis="0 0 1" range="-0.785398 1.5708" actuatorfrcrange="-20 20"/>
        <geom type="mesh" contype="0" conaffinity="0" group="1" density="0" rgba="0.8 0.8 0.8 1" mesh="arm_right_shoulder_pitch_visual"/>
        <body name="arm_right_shoulder_roll" pos="-0.0255 0 0.043" quat="0.701057 0.0922949 -0.701058 -0.0922949">
          <inertial pos="-4.27603e-05 0.0715053 -0.0278824" quat="0.681009 0.732275 -0.000118334 -0.000705712" mass="0.416078" diaginertia="0.000651025 0.000522347 0.000336008"/>
          <joint name="arm_right_shoulder_roll_joint" pos="0 0 0" axis="0 0 1" range="0 1.5708" actuatorfrcrange="-20 20"/>
          <geom type="mesh" contype="0" conaffinity="0" group="1" density="0" rgba="0.8 0.8 0.8 1" mesh="arm_right_shoulder_roll_visual"/>
          <body name="arm_right_shoulder_yaw" pos="0 0.123 -0.0255" quat="9.38184e-07 9.38187e-07 0.707108 0.707105">
            <inertial pos="-0.00781722 -1.63693e-05 0.0404875" quat="0.480073 0.516042 0.529544 0.472033" mass="0.329199" diaginertia="0.00024084 0.000215005 0.000195235"/>
            <joint name="arm_right_shoulder_yaw_joint" pos="0 0 0" axis="0 0 1" range="-0.785398 0.785398" actuatorfrcrange="-20 20"/>
            <geom size="0.04 0.075" pos="0 0 -0.035" quat="1.32679e-06 1 0 0" type="cylinder"/>
            <geom type="mesh" contype="0" conaffinity="0" group="1" density="0" rgba="0.8 0.8 0.8 1" mesh="arm_right_shoulder_yaw_visual"/>
            <body name="arm_right_elbow_pitch" pos="0.0245 0 0.043" quat="0.499998 0.5 0.500002 0.5">
              <inertial pos="-4.27603e-05 0.0715053 -0.0278824" quat="0.681009 0.732275 -0.000118334 -0.000705712" mass="0.416078" diaginertia="0.000651025 0.000522347 0.000336008"/>
              <joint name="arm_right_elbow_pitch_joint" pos="0 0 0" axis="0 0 1" range="-1.5708 0" actuatorfrcrange="-20 20"/>
              <geom type="mesh" contype="0" conaffinity="0" group="1" density="0" rgba="0.8 0.8 0.8 1" mesh="arm_right_elbow_pitch_visual"/>
              <body name="arm_right_elbow_roll" pos="0 0.123 -0.0255" quat="9.38184e-07 9.38187e-07 -0.707108 -0.707105">
                <inertial pos="-0.0134599 0.00247969 0.0539928" quat="0.743582 0.0884785 0.103429 0.654644" mass="0.292567" diaginertia="0.00055922 0.000523904 0.000133438"/>
                <joint name="arm_right_elbow_roll_joint" pos="0 0 0" axis="0 0 1" range="-0.785398 0.785398" actuatorfrcrange="-20 20"/>
                <geom size="0.03 0.06" pos="0 0 -0.01" quat="1.32679e-06 -1 0 0" type="cylinder"/>
                <geom type="mesh" contype="0" conaffinity="0" group="1" density="0" rgba="0.8 0.8 0.8 1" mesh="arm_right_elbow_roll_visual"/>
                <geom quat="9.38184e-07 -0.707105 0.707108 -9.38187e-07" type="mesh" contype="0" conaffinity="0" group="1" density="0" rgba="0.8 0.8 0.8 1" mesh="arm_right_hand_link_visual"/>
              </body>
            </body>
          </body>
        </body>
      </body>
      <body name="leg_left_hip_roll" pos="-0.0290919 0.08 -0.057369" quat="0.92388 0 0.382683 0">
        <inertial pos="-0.00410941 -0.000112596 -0.0464623" quat="0.998579 -0.0134956 0.0323242 0.0401687" mass="0.83786" diaginertia="0.00098151 0.00089565 0.000726479"/>
        <joint name="leg_left_hip_roll_joint" pos="0 0 0" axis="0 0 1" range="-0.174533 1.5708" actuatorfrcrange="-20 20"/>
        <geom type="mesh" contype="0" conaffinity="0" group="1" density="0" rgba="0.8 0.8 0.8 1" mesh="leg_left_hip_roll_visual"/>
        <body name="leg_left_hip_yaw" pos="0.027 0 -0.052" quat="0.499998 -0.5 0.500002 -0.5">
          <inertial pos="-0.00411632 -8.63203e-05 0.0463382" quat="0.999084 -0.0161651 -0.0382793 -0.010234" mass="0.837683" diaginertia="0.000980566 0.000898328 0.00072259"/>
          <joint name="leg_left_hip_yaw_joint" pos="0 0 0" axis="0 0 1" range="-0.981748 0.589049" actuatorfrcrange="-20 20"/>
          <geom type="mesh" contype="0" conaffinity="0" group="1" density="0" rgba="0.8 0.8 0.8 1" mesh="leg_left_hip_yaw_visual"/>
          <body name="leg_left_hip_pitch" pos="0.027 0 0.052" quat="0.65328 0.270598 -0.653282 -0.270598">
            <inertial pos="0.0030405 0.120388 0.0210924" quat="0.761917 0.646837 0.0270389 0.0188058" mass="0.947974" diaginertia="0.00287266 0.00264321 0.000972851"/>
            <joint name="leg_left_hip_pitch_joint" pos="0 0 0" axis="0 0 1" range="-1.89805 0.981748" actuatorfrcrange="-20 20"/>
            <geom size="0.05 0.065" pos="0.00597627 0.039 0.0295" quat="0.499998 0.5 0.5 -0.500002" type="cylinder"/>
            <geom type="mesh" contype="0" conaffinity="0" group="1" density="0" rgba="0.8 0.8 0.8 1" mesh="leg_left_hip_pitch_visual"/>
            <body name="leg_left_knee_pitch" pos="0 0.15 -0.018" quat="1.32679e-06 0 0 -1">
              <inertial pos="-4.09608e-05 -0.112761 0.025479" quat="0.714112 0.700027 -0.00189797 0.00175807" mass="0.66094" diaginertia="0.00232496 0.00206094 0.000566882"/>
              <joint name="leg_left_knee_pitch_joint" pos="0 0 0" axis="0 0 1" range="0 2.44346" actuatorfrcrange="-20 20"/>
              <geom size="0.04 0.075" pos="0 -0.115 0.022" quat="0.499998 -0.5 0.5 0.500002" type="cylinder"/>
              <geom type="mesh" contype="0" conaffinity="0" group="1" density="0" rgba="0.8 0.8 0.8 1" mesh="leg_left_knee_pitch_visual"/>
              <body name="leg_left_ankle_pitch" pos="0 -0.16 -0.003" quat="1.32679e-06 0 0 -1">
                <inertial pos="0.0131065 0.0273743 0.0274153" quat="0.97446 -0.0895638 0.0341084 -0.203084" mass="0.106196" diaginertia="0.000199494 0.000133736 7.96933e-05"/>
                <joint name="leg_left_ankle_pitch_joint" pos="0 0 0" axis="0 0 1" range="-0.785398 0.785398" actuatorfrcrange="-20 20"/>
                <geom type="mesh" contype="0" conaffinity="0" group="1" density="0" rgba="0.8 0.8 0.8 1" mesh="leg_left_ankle_pitch_visual"/>
                <body name="leg_left_ankle_roll" pos="0.03 0.05 0.025" quat="0.707105 0 0.707108 0">
                  <inertial pos="2.38759e-05 0.0235917 0.0199185" quat="0.998505 0.0544846 8.31116e-05 0.00434196" mass="0.678609" diaginertia="0.00195688 0.00190404 0.000560568"/>
                  <joint name="leg_left_ankle_roll_joint" pos="0 0 0" axis="0 0 1" range="-0.261799 0.261799" actuatorfrcrange="-20 20"/>
                  <geom size="0.036 0.11 0.02" pos="0 0.03 0.006" quat="0.707105 0.707108 0 0" type="box"/>
                  <geom type="mesh" contype="0" conaffinity="0" group="1" density="0" rgba="0.8 0.8 0.8 1" mesh="leg_left_ankle_roll_visual"/>
                </body>
              </body>
            </body>
          </body>
        </body>
      </body>
      <body name="leg_right_hip_roll" pos="-0.0290919 -0.08 -0.057369" quat="1.2258e-06 0.382683 -5.07742e-07 0.92388">
        <inertial pos="0.00410941 -0.00018505 -0.0464478" quat="0.99915 -0.0125114 -0.0311449 -0.0239221" mass="0.83786" diaginertia="0.000980934 0.000896266 0.000726135"/>
        <joint name="leg_right_hip_roll_joint" pos="0 0 0" axis="0 0 1" range="-1.5708 0.174533" actuatorfrcrange="-20 20"/>
        <geom type="mesh" contype="0" conaffinity="0" group="1" density="0" rgba="0.8 0.8 0.8 1" mesh="leg_right_hip_roll_visual"/>
        <body name="leg_right_hip_yaw" pos="-0.027 0 -0.052" quat="0.499998 -0.5 -0.500002 0.5">
          <inertial pos="0.00411632 -1.3851e-05 0.0463238" quat="0.999168 -0.0154252 0.0370844 -0.00703098" mass="0.837683" diaginertia="0.00098034 0.000898597 0.000722286"/>
          <joint name="leg_right_hip_yaw_joint" pos="0 0 0" axis="0 0 1" range="-0.589049 0.981748" actuatorfrcrange="-20 20"/>
          <geom type="mesh" contype="0" conaffinity="0" group="1" density="0" rgba="0.8 0.8 0.8 1" mesh="leg_right_hip_yaw_visual"/>
          <body name="leg_right_hip_pitch" pos="-0.027 0 0.052" quat="0.65328 0.270598 -0.653282 -0.270598">
            <inertial pos="0.00319928 0.120388 -0.0210924" quat="0.646378 0.762188 0.00805307 0.0346537" mass="0.947974" diaginertia="0.00287232 0.00264204 0.000972473"/>
            <joint name="leg_right_hip_pitch_joint" pos="0 0 0" axis="0 0 1" range="-1.89805 0.981748" actuatorfrcrange="-20 20"/>
            <geom size="0.05 0.065" pos="0.00597627 0.039 -0.0295" quat="0.499998 0.5 0.5 -0.500002" type="cylinder"/>
            <geom type="mesh" contype="0" conaffinity="0" group="1" density="0" rgba="0.8 0.8 0.8 1" mesh="leg_right_hip_pitch_visual"/>
            <body name="leg_right_knee_pitch" pos="0 0.15 0.018">
              <inertial pos="-5.03974e-05 0.112761 -0.025479" quat="0.714113 0.700027 0.00181341 -0.00129911" mass="0.66094" diaginertia="0.00232496 0.00206094 0.00056688"/>
              <joint name="leg_right_knee_pitch_joint" pos="0 0 0" axis="0 0 1" range="0 2.44346" actuatorfrcrange="-20 20"/>
              <geom size="0.04 0.075" pos="0 0.115 -0.022" quat="0.499998 0.5 0.5 -0.500002" type="cylinder"/>
              <geom type="mesh" contype="0" conaffinity="0" group="1" density="0" rgba="0.8 0.8 0.8 1" mesh="leg_right_knee_pitch_visual"/>
              <body name="leg_right_ankle_pitch" pos="0 0.16 0.003">
                <inertial pos="0.0131065 0.0273743 -0.0274153" quat="0.97446 0.0895638 -0.0341084 -0.203084" mass="0.106196" diaginertia="0.000199494 0.000133736 7.96934e-05"/>
                <joint name="leg_right_ankle_pitch_joint" pos="0 0 0" axis="0 0 1" range="-0.785398 0.785398" actuatorfrcrange="-20 20"/>
                <geom type="mesh" contype="0" conaffinity="0" group="1" density="0" rgba="0.8 0.8 0.8 1" mesh="leg_right_ankle_pitch_visual"/>
                <body name="leg_right_ankle_roll" pos="0.03 0.05 -0.025" quat="0.707105 0 0.707108 0">
                  <inertial pos="2.38759e-05 0.0235917 0.0199185" quat="0.998505 0.0544846 8.31116e-05 0.00434196" mass="0.678609" diaginertia="0.00195688 0.00190404 0.000560568"/>
                  <joint name="leg_right_ankle_roll_joint" pos="0 0 0" axis="0 0 1" range="-0.261799 0.261799" actuatorfrcrange="-20 20"/>
                  <geom size="0.036 0.11 0.02" pos="0 0.03 0.006" quat="0.707105 0.707108 0 0" type="box"/>
                  <geom type="mesh" contype="0" conaffinity="0" group="1" density="0" rgba="0.8 0.8 0.8 1" mesh="leg_right_ankle_roll_visual"/>
                </body>
              </body>
            </body>
          </body>
        </body>
      </body>
    </body>
  </worldbody>

  <actuator>
    <motor name="arm_left_shoulder_pitch"   gear="1" joint="arm_left_shoulder_pitch_joint"/>
    <motor name="arm_left_shoulder_roll"    gear="1" joint="arm_left_shoulder_roll_joint"/>
    <motor name="arm_left_shoulder_yaw"     gear="1" joint="arm_left_shoulder_yaw_joint"/>
    <motor name="arm_left_elbow_pitch"      gear="1" joint="arm_left_elbow_pitch_joint"/>
    <motor name="arm_left_elbow_roll"       gear="1" joint="arm_left_elbow_roll_joint"/>
    <motor name="arm_right_shoulder_pitch"  gear="1" joint="arm_right_shoulder_pitch_joint"/>
    <motor name="arm_right_shoulder_roll"   gear="1" joint="arm_right_shoulder_roll_joint"/>
    <motor name="arm_right_shoulder_yaw"    gear="1" joint="arm_right_shoulder_yaw_joint"/>
    <motor name="arm_right_elbow_pitch"     gear="1" joint="arm_right_elbow_pitch_joint"/>
    <motor name="arm_right_elbow_roll"      gear="1" joint="arm_right_elbow_roll_joint"/>
    <motor name="leg_left_hip_roll"         gear="1" joint="leg_left_hip_roll_joint"/>
    <motor name="leg_left_hip_yaw"          gear="1" joint="leg_left_hip_yaw_joint"/>
    <motor name="leg_left_hip_pitch"        gear="1" joint="leg_left_hip_pitch_joint"/>
    <motor name="leg_left_knee_pitch"       gear="1" joint="leg_left_knee_pitch_joint"/>
    <motor name="leg_left_ankle_pitch"      gear="1" joint="leg_left_ankle_pitch_joint"/>
    <motor name="leg_left_ankle_roll"       gear="1" joint="leg_left_ankle_roll_joint"/>
    <motor name="leg_right_hip_roll"        gear="1" joint="leg_right_hip_roll_joint"/>
    <motor name="leg_right_hip_yaw"         gear="1" joint="leg_right_hip_yaw_joint"/>
    <motor name="leg_right_hip_pitch"       gear="1" joint="leg_right_hip_pitch_joint"/>
    <motor name="leg_right_knee_pitch"      gear="1" joint="leg_right_knee_pitch_joint"/>
    <motor name="leg_right_ankle_pitch"     gear="1" joint="leg_right_ankle_pitch_joint"/>
    <motor name="leg_right_ankle_roll"      gear="1" joint="leg_right_ankle_roll_joint"/>
  </actuator>

  <sensor>
    <jointpos name="arm_left_shoulder_pitch_pos"  joint="arm_left_shoulder_pitch_joint"/>
    <jointpos name="arm_left_shoulder_roll_pos"   joint="arm_left_shoulder_roll_joint"/>
    <jointpos name="arm_left_shoulder_yaw_pos"    joint="arm_left_shoulder_yaw_joint"/>
    <jointpos name="arm_left_elbow_pitch_pos"     joint="arm_left_elbow_pitch_joint"/>
    <jointpos name="arm_left_elbow_roll_pos"      joint="arm_left_elbow_roll_joint"/>
    <jointpos name="arm_right_shoulder_pitch_pos" joint="arm_right_shoulder_pitch_joint"/>
    <jointpos name="arm_right_shoulder_roll_pos"  joint="arm_right_shoulder_roll_joint"/>
    <jointpos name="arm_right_shoulder_yaw_pos"   joint="arm_right_shoulder_yaw_joint"/>
    <jointpos name="arm_right_elbow_pitch_pos"    joint="arm_right_elbow_pitch_joint"/>
    <jointpos name="arm_right_elbow_roll_pos"     joint="arm_right_elbow_roll_joint"/>
    <jointpos name="leg_left_hip_roll_pos"        joint="leg_left_hip_roll_joint"/>
    <jointpos name="leg_left_hip_yaw_pos"         joint="leg_left_hip_yaw_joint"/>
    <jointpos name="leg_left_hip_pitch_pos"       joint="leg_left_hip_pitch_joint"/>
    <jointpos name="leg_left_knee_pitch_pos"      joint="leg_left_knee_pitch_joint"/>
    <jointpos name="leg_left_ankle_pitch_pos"     joint="leg_left_ankle_pitch_joint"/>
    <jointpos name="leg_left_ankle_roll_pos"      joint="leg_left_ankle_roll_joint"/>
    <jointpos name="leg_right_hip_roll_pos"       joint="leg_right_hip_roll_joint"/>
    <jointpos name="leg_right_hip_yaw_pos"        joint="leg_right_hip_yaw_joint"/>
    <jointpos name="leg_right_hip_pitch_pos"      joint="leg_right_hip_pitch_joint"/>
    <jointpos name="leg_right_knee_pitch_pos"     joint="leg_right_knee_pitch_joint"/>
    <jointpos name="leg_right_ankle_pitch_pos"    joint="leg_right_ankle_pitch_joint"/>
    <jointpos name="leg_right_ankle_roll_pos"     joint="leg_right_ankle_roll_joint"/>

    <jointvel name="arm_left_shoulder_pitch_vel"  joint="arm_left_shoulder_pitch_joint"/>
    <jointvel name="arm_left_shoulder_roll_vel"   joint="arm_left_shoulder_roll_joint"/>
    <jointvel name="arm_left_shoulder_yaw_vel"    joint="arm_left_shoulder_yaw_joint"/>
    <jointvel name="arm_left_elbow_pitch_vel"     joint="arm_left_elbow_pitch_joint"/>
    <jointvel name="arm_left_elbow_roll_vel"      joint="arm_left_elbow_roll_joint"/>
    <jointvel name="arm_right_shoulder_pitch_vel" joint="arm_right_shoulder_pitch_joint"/>
    <jointvel name="arm_right_shoulder_roll_vel"  joint="arm_right_shoulder_roll_joint"/>
    <jointvel name="arm_right_shoulder_yaw_vel"   joint="arm_right_shoulder_yaw_joint"/>
    <jointvel name="arm_right_elbow_pitch_vel"    joint="arm_right_elbow_pitch_joint"/>
    <jointvel name="arm_right_elbow_roll_vel"     joint="arm_right_elbow_roll_joint"/>
    <jointvel name="leg_left_hip_roll_vel"        joint="leg_left_hip_roll_joint"/>
    <jointvel name="leg_left_hip_yaw_vel"         joint="leg_left_hip_yaw_joint"/>
    <jointvel name="leg_left_hip_pitch_vel"       joint="leg_left_hip_pitch_joint"/>
    <jointvel name="leg_left_knee_pitch_vel"      joint="leg_left_knee_pitch_joint"/>
    <jointvel name="leg_left_ankle_pitch_vel"     joint="leg_left_ankle_pitch_joint"/>
    <jointvel name="leg_left_ankle_roll_vel"      joint="leg_left_ankle_roll_joint"/>
    <jointvel name="leg_right_hip_roll_vel"       joint="leg_right_hip_roll_joint"/>
    <jointvel name="leg_right_hip_yaw_vel"        joint="leg_right_hip_yaw_joint"/>
    <jointvel name="leg_right_hip_pitch_vel"      joint="leg_right_hip_pitch_joint"/>
    <jointvel name="leg_right_knee_pitch_vel"     joint="leg_right_knee_pitch_joint"/>
    <jointvel name="leg_right_ankle_pitch_vel"    joint="leg_right_ankle_pitch_joint"/>
    <jointvel name="leg_right_ankle_roll_vel"     joint="leg_right_ankle_roll_joint"/>

    <jointactuatorfrc name="arm_left_shoulder_pitch_torque"   joint="arm_left_shoulder_pitch_joint"/>
    <jointactuatorfrc name="arm_left_shoulder_roll_torque"    joint="arm_left_shoulder_roll_joint"/>
    <jointactuatorfrc name="arm_left_shoulder_yaw_torque"     joint="arm_left_shoulder_yaw_joint"/>
    <jointactuatorfrc name="arm_left_elbow_pitch_torque"      joint="arm_left_elbow_pitch_joint"/>
    <jointactuatorfrc name="arm_left_elbow_roll_torque"       joint="arm_left_elbow_roll_joint"/>
    <jointactuatorfrc name="arm_right_shoulder_pitch_torque"  joint="arm_right_shoulder_pitch_joint"/>
    <jointactuatorfrc name="arm_right_shoulder_roll_torque"   joint="arm_right_shoulder_roll_joint"/>
    <jointactuatorfrc name="arm_right_shoulder_yaw_torque"    joint="arm_right_shoulder_yaw_joint"/>
    <jointactuatorfrc name="arm_right_elbow_pitch_torque"     joint="arm_right_elbow_pitch_joint"/>
    <jointactuatorfrc name="arm_right_elbow_roll_torque"      joint="arm_right_elbow_roll_joint"/>
    <jointactuatorfrc name="leg_left_hip_roll_torque"         joint="leg_left_hip_roll_joint"/>
    <jointactuatorfrc name="leg_left_hip_yaw_torque"          joint="leg_left_hip_yaw_joint"/>
    <jointactuatorfrc name="leg_left_hip_pitch_torque"        joint="leg_left_hip_pitch_joint"/>
    <jointactuatorfrc name="leg_left_knee_pitch_torque"       joint="leg_left_knee_pitch_joint"/>
    <jointactuatorfrc name="leg_left_ankle_pitch_torque"      joint="leg_left_ankle_pitch_joint"/>
    <jointactuatorfrc name="leg_left_ankle_roll_torque"       joint="leg_left_ankle_roll_joint"/>
    <jointactuatorfrc name="leg_right_hip_roll_torque"        joint="leg_right_hip_roll_joint"/>
    <jointactuatorfrc name="leg_right_hip_yaw_torque"         joint="leg_right_hip_yaw_joint"/>
    <jointactuatorfrc name="leg_right_hip_pitch_torque"       joint="leg_right_hip_pitch_joint"/>
    <jointactuatorfrc name="leg_right_knee_pitch_torque"      joint="leg_right_knee_pitch_joint"/>
    <jointactuatorfrc name="leg_right_ankle_pitch_torque"     joint="leg_right_ankle_pitch_joint"/>
    <jointactuatorfrc name="leg_right_ankle_roll_torque"      joint="leg_right_ankle_roll_joint"/>

    <framequat name="imu_quat" objtype="site" objname="imu" />
    <gyro name="imu_gyro" site="imu" />
    <accelerometer name="imu_acc" site="imu" />
    <framepos name="frame_pos" objtype="site" objname="imu" />
    <framelinvel name="frame_vel" objtype="site" objname="imu" />
  </sensor>
</mujoco>
