<robot name="berkeley-humanoid-lite" version="2025-03-12">
  <mujoco>
    <compiler meshdir="../meshes/" balanceinertia="true" discardvisual="false"/>
  </mujoco>
    <link name="base">
        <!-- Shapes for aluminum_extrusion_400mm_3 -->
        <!-- Shapes for aluminum_extrusion_150mm_2 -->
        <!-- Shapes for aluminum_extrusion_400mm_4 -->
        <!-- Shapes for battery_mount -->
        <!-- Shapes for housing_middle -->
        <!-- Shapes for stopper_y_l -->
        <!-- Shapes for aluminum_extrusion_400mm_1 -->
        <!-- Shapes for aluminum_extrusion_100mm_3 -->
        <!-- Shapes for stopper_y_r -->
        <!-- Shapes for aluminum_extrusion_400mm_2 -->
        <!-- Shapes for meter_mount -->
        <!-- Shapes for nuc_mount -->
        <!-- Shapes for aluminum_extrusion_200mm_1 -->
        <!-- Shapes for imu_arduino_mount -->
        <!-- Shapes for aluminum_extrusion_150mm_1 -->
        <!-- Shapes for aluminum_extrusion_100mm_center -->
        <collision>
            <origin xyz="0 0 0.11" rpy="0 0 -1.5708"/>
            <geometry>
                <box size="0.15 0.14 0.23"/>
            </geometry>
        </collision>
        <!-- Shapes for aluminum_extrusion_200mm_2 -->
        <!-- Shapes for turnigy_graphene_lipo -->
        <!-- Shapes for nuc_mount -->
        <!-- Shapes for aluminum_extrusion_100mm_4 -->
        <!-- Shapes for beelink_nuc_computer -->
        <!-- Shapes for output_shaft_front -->
        <!-- Shapes for motor_shell -->
        <!-- Shapes for housing_front -->
        <!-- Shapes for housing_rear -->
        <!-- Shapes for output_shaft_front -->
        <!-- Shapes for motor_shell -->
        <!-- Shapes for housing_front -->
        <!-- Shapes for housing_rear -->
        <!-- Shapes for base_housing_middle -->
        <!-- Shapes for base_housing_middle -->
        <!-- Shapes for shoulder_middle -->
        <!-- Shapes for base_housing_front -->
        <!-- Shapes for base_housing_front -->
        <!-- Shapes for output_shaft_front -->
        <!-- Shapes for motor_shell -->
        <!-- Shapes for housing_front -->
        <!-- Shapes for housing_rear -->
        <!-- Shapes for output_shaft_front -->
        <!-- Shapes for motor_shell -->
        <!-- Shapes for housing_front -->
        <!-- Shapes for housing_rear -->
        <visual>
            <origin xyz="0 0 0" rpy="0 0 0"/>
            <geometry>
                <mesh filename="../meshes/base_visual.stl"/>
            </geometry>
            <material name="base_material">
                <color rgba="0.8 0.8 0.8 1.0"/>
            </material>
        </visual>
        <inertial>
            <origin xyz="-0.00307744 0.000105799 0.0742651" rpy="0 0 0"/>
            <mass value="4.47154"/>
            <inertia ixx="0.0672115" ixy="3.40256e-06" ixz="-0.00130551" iyy="0.0454326" iyz="-5.1283e-05" izz="0.0320938"/>
        </inertial>
    </link>

    <link name="imu">
        <!-- Shapes for imu_link -->
        <visual>
            <origin xyz="0 0 0" rpy="0 0 0"/>
            <geometry>
                <mesh filename="../meshes/imu_visual.stl"/>
            </geometry>
            <material name="imu_material">
                <color rgba="0.8 0.8 0.8 1.0"/>
            </material>
        </visual>
        <inertial>
            <origin xyz="0 0 0.0025" rpy="0 0 0"/>
            <mass value="0.00197704"/>
            <inertia ixx="1.11441e-07" ixy="0" ixz="0" iyy="4.06118e-08" iyz="0" izz="1.43815e-07"/>
        </inertial>
    </link>

    <joint name="imu" type="fixed">
        <origin xyz="0.061722 0 0.08" rpy="0 0 0"/>
        <parent link="base"/>
        <child link="imu"/>
        <axis xyz="0 0 1"/>
        <limit effort="20" velocity="15" />
        <joint_properties friction="0.0"/>
    </joint>

    <link name="arm_left_shoulder_pitch">
        <!-- Shapes for upperarm_x_housing_middle -->
        <!-- Shapes for rear_struct -->
        <!-- Shapes for housing_front -->
        <!-- Shapes for output_shaft_front -->
        <!-- Shapes for motor_shell -->
        <!-- Shapes for housing_rear -->
        <visual>
            <origin xyz="0 0 0" rpy="0 0 0"/>
            <geometry>
                <mesh filename="../meshes/arm_left_shoulder_pitch_visual.stl"/>
            </geometry>
            <material name="arm_left_shoulder_pitch_material">
                <color rgba="0.8 0.8 0.8 1.0"/>
            </material>
        </visual>
        <inertial>
            <origin xyz="-0.00661228 -8.80749e-05 0.0396144" rpy="0 0 0"/>
            <mass value="0.342876"/>
            <inertia ixx="0.000218285" ixy="-1.17021e-06" ixz="1.05191e-05" iyy="0.000260325" iyz="-4.52438e-07" izz="0.00022463"/>
        </inertial>
    </link>

    <link name="arm_left_shoulder_roll">
        <!-- Shapes for elbow_mount_2 -->
        <!-- Shapes for elbow_mount -->
        <!-- Shapes for housing_front -->
        <!-- Shapes for output_shaft_front -->
        <!-- Shapes for motor_shell -->
        <!-- Shapes for housing_rear -->
        <visual>
            <origin xyz="0 0 0" rpy="0 0 0"/>
            <geometry>
                <mesh filename="../meshes/arm_left_shoulder_roll_visual.stl"/>
            </geometry>
            <material name="arm_left_shoulder_roll_material">
                <color rgba="0.8 0.8 0.8 1.0"/>
            </material>
        </visual>
        <inertial>
            <origin xyz="-4.27603e-05 0.0715053 -0.0278824" rpy="0 0 0"/>
            <mass value="0.416078"/>
            <inertia ixx="0.000651024" ixy="-3.68022e-07" ixz="-1.28385e-07" iyy="0.000336987" iyz="-1.34653e-05" izz="0.000521369"/>
        </inertial>
    </link>

    <link name="arm_left_shoulder_yaw">
        <!-- Shapes for geometry_stud_upperarm -->
        <collision>
            <origin xyz="0 0 -0.035" rpy="-3.14159 0 3.14159"/>
            <geometry>
                <cylinder length="0.15" radius="0.04"/>
            </geometry>
        </collision>
        <!-- Shapes for rear_struct -->
        <!-- Shapes for upperarm_x_housing_middle -->
        <!-- Shapes for housing_front -->
        <!-- Shapes for output_shaft_front -->
        <!-- Shapes for motor_shell -->
        <!-- Shapes for housing_rear -->
        <visual>
            <origin xyz="0 0 0" rpy="0 0 0"/>
            <geometry>
                <mesh filename="../meshes/arm_left_shoulder_yaw_visual.stl"/>
            </geometry>
            <material name="arm_left_shoulder_yaw_material">
                <color rgba="0.8 0.8 0.8 1.0"/>
            </material>
        </visual>
        <inertial>
            <origin xyz="-0.00781722 -9.17114e-05 0.0409759" rpy="0 0 0"/>
            <mass value="0.329199"/>
            <inertia ixx="0.000196136" ixy="-1.164e-06" ixz="8.20811e-06" iyy="0.000241556" iyz="-4.93374e-07" izz="0.000214842"/>
        </inertial>
    </link>

    <link name="arm_left_elbow_pitch">
        <!-- Shapes for elbow_mount_2 -->
        <!-- Shapes for elbow_mount -->
        <!-- Shapes for housing_front -->
        <!-- Shapes for output_shaft_front -->
        <!-- Shapes for motor_shell -->
        <!-- Shapes for housing_rear -->
        <visual>
            <origin xyz="0 0 0" rpy="0 0 0"/>
            <geometry>
                <mesh filename="../meshes/arm_left_elbow_pitch_visual.stl"/>
            </geometry>
            <material name="arm_left_elbow_pitch_material">
                <color rgba="0.8 0.8 0.8 1.0"/>
            </material>
        </visual>
        <inertial>
            <origin xyz="-4.27603e-05 0.0715053 -0.0278824" rpy="0 0 0"/>
            <mass value="0.416078"/>
            <inertia ixx="0.000651024" ixy="-3.68022e-07" ixz="-1.28385e-07" iyy="0.000336987" iyz="-1.34653e-05" izz="0.000521369"/>
        </inertial>
    </link>

    <link name="arm_left_elbow_roll">
        <!-- Shapes for geometry_stud_lowerarm -->
        <collision>
            <origin xyz="0 0 -0.01" rpy="3.14159 0 0"/>
            <geometry>
                <cylinder length="0.12" radius="0.03"/>
            </geometry>
        </collision>
        <visual>
            <origin xyz="0 0 0" rpy="0 0 0"/>
            <geometry>
                <mesh filename="../meshes/arm_left_elbow_roll_visual.stl"/>
            </geometry>
            <material name="arm_left_elbow_roll_material">
                <color rgba="0.8 0.8 0.8 1.0"/>
            </material>
        </visual>
        <inertial>
            <origin xyz="0 0 0.005" rpy="0 0 0"/>
            <mass value="0.000826239"/>
            <inertia ixx="1.20493e-08" ixy="0" ixz="0" iyy="1.20493e-08" iyz="0" izz="1.0328e-08"/>
        </inertial>
    </link>

    <link name="arm_left_hand_link">
        <!-- Shapes for wrist -->
        <!-- Shapes for claw -->
        <!-- Shapes for linkage_1 -->
        <!-- Shapes for linkage_2 -->
        <!-- Shapes for base_plate -->
        <!-- Shapes for claw -->
        <!-- Shapes for linkage_1 -->
        <!-- Shapes for linkage_2 -->
        <!-- Shapes for metal_case -->
        <!-- Shapes for bottom_shell -->
        <!-- Shapes for top_shell -->
        <!-- Shapes for shaft -->
        <visual>
            <origin xyz="0 0 0" rpy="0 0 0"/>
            <geometry>
                <mesh filename="../meshes/arm_left_hand_link_visual.stl"/>
            </geometry>
            <material name="arm_left_hand_link_material">
                <color rgba="0.8 0.8 0.8 1.0"/>
            </material>
        </visual>
        <inertial>
            <origin xyz="-0.00248666 0.0134979 -0.0541316" rpy="0 0 0"/>
            <mass value="0.291741"/>
            <inertia ixx="0.000556491" ixy="3.82363e-06" ixz="-2.67254e-06" iyy="0.000494025" iyz="-0.000102102" izz="0.000161723"/>
        </inertial>
    </link>

    <joint name="arm_left_hand_l" type="fixed">
        <origin xyz="0 0 0" rpy="3.14159 0 -1.5708"/>
        <parent link="arm_left_elbow_roll"/>
        <child link="arm_left_hand_link"/>
        <axis xyz="0 0 1"/>
        <limit effort="20" velocity="15" />
        <joint_properties friction="0.0"/>
    </joint>

    <joint name="arm_left_elbow_roll_joint" type="revolute">
        <origin xyz="0 0.123 -0.0255" rpy="-1.5708 0 0"/>
        <parent link="arm_left_elbow_pitch"/>
        <child link="arm_left_elbow_roll"/>
        <axis xyz="0 0 1"/>
        <limit effort="20" velocity="15" lower="-0.785398" upper="0.785398"/>
        <joint_properties friction="0.0"/>
    </joint>

    <joint name="arm_left_elbow_pitch_joint" type="revolute">
        <origin xyz="0.0245 0 0.043" rpy="1.5708 0 1.5708"/>
        <parent link="arm_left_shoulder_yaw"/>
        <child link="arm_left_elbow_pitch"/>
        <axis xyz="0 0 1"/>
        <limit effort="20" velocity="15" lower="-0" upper="1.5708"/>
        <joint_properties friction="0.0"/>
    </joint>

    <joint name="arm_left_shoulder_yaw_joint" type="revolute">
        <origin xyz="0 0.123 -0.0255" rpy="-1.5708 0 0"/>
        <parent link="arm_left_shoulder_roll"/>
        <child link="arm_left_shoulder_yaw"/>
        <axis xyz="0 0 1"/>
        <limit effort="20" velocity="15" lower="-0.785398" upper="0.785398"/>
        <joint_properties friction="0.0"/>
    </joint>

    <joint name="arm_left_shoulder_roll_joint" type="revolute">
        <origin xyz="0.0255 0 0.043" rpy="1.5708 1.309 1.5708"/>
        <parent link="arm_left_shoulder_pitch"/>
        <child link="arm_left_shoulder_roll"/>
        <axis xyz="0 0 1"/>
        <limit effort="20" velocity="15" lower="-1.5708" upper="-0"/>
        <joint_properties friction="0.0"/>
    </joint>

    <joint name="arm_left_shoulder_pitch_joint" type="revolute">
        <origin xyz="0 0.133 0.164028" rpy="-1.5708 0 0"/>
        <parent link="base"/>
        <child link="arm_left_shoulder_pitch"/>
        <axis xyz="0 0 1"/>
        <limit effort="20" velocity="15" lower="-1.5708" upper="0.785398"/>
        <joint_properties friction="0.0"/>
    </joint>

    <link name="arm_right_shoulder_pitch">
        <!-- Shapes for upperarm_x_housing_middle -->
        <!-- Shapes for rear_struct -->
        <!-- Shapes for housing_front -->
        <!-- Shapes for output_shaft_front -->
        <!-- Shapes for motor_shell -->
        <!-- Shapes for housing_rear -->
        <visual>
            <origin xyz="0 0 0" rpy="0 0 0"/>
            <geometry>
                <mesh filename="../meshes/arm_right_shoulder_pitch_visual.stl"/>
            </geometry>
            <material name="arm_right_shoulder_pitch_material">
                <color rgba="0.8 0.8 0.8 1.0"/>
            </material>
        </visual>
        <inertial>
            <origin xyz="0.00661228 -1.57066e-05 0.0397088" rpy="0 0 0"/>
            <mass value="0.342876"/>
            <inertia ixx="0.000218503" ixy="2.55599e-07" ixz="-1.17928e-05" iyy="0.000260541" iyz="5.72405e-07" izz="0.000224632"/>
        </inertial>
    </link>

    <link name="arm_right_shoulder_roll">
        <!-- Shapes for elbow_mount_2 -->
        <!-- Shapes for elbow_mount -->
        <!-- Shapes for housing_front -->
        <!-- Shapes for output_shaft_front -->
        <!-- Shapes for motor_shell -->
        <!-- Shapes for housing_rear -->
        <visual>
            <origin xyz="0 0 0" rpy="0 0 0"/>
            <geometry>
                <mesh filename="../meshes/arm_right_shoulder_roll_visual.stl"/>
            </geometry>
            <material name="arm_right_shoulder_roll_material">
                <color rgba="0.8 0.8 0.8 1.0"/>
            </material>
        </visual>
        <inertial>
            <origin xyz="-4.27603e-05 0.0715053 -0.0278824" rpy="0 0 0"/>
            <mass value="0.416078"/>
            <inertia ixx="0.000651024" ixy="-3.68022e-07" ixz="-1.28385e-07" iyy="0.000336987" iyz="-1.34653e-05" izz="0.000521369"/>
        </inertial>
    </link>

    <link name="arm_right_shoulder_yaw">
        <!-- Shapes for geometry_stud_upperarm -->
        <collision>
            <origin xyz="0 0 -0.035" rpy="3.14159 0 0"/>
            <geometry>
                <cylinder length="0.15" radius="0.04"/>
            </geometry>
        </collision>
        <!-- Shapes for rear_struct -->
        <!-- Shapes for upperarm_x_housing_middle -->
        <!-- Shapes for housing_front -->
        <!-- Shapes for output_shaft_front -->
        <!-- Shapes for motor_shell -->
        <!-- Shapes for housing_rear -->
        <visual>
            <origin xyz="0 0 0" rpy="0 0 0"/>
            <geometry>
                <mesh filename="../meshes/arm_right_shoulder_yaw_visual.stl"/>
            </geometry>
            <material name="arm_right_shoulder_yaw_material">
                <color rgba="0.8 0.8 0.8 1.0"/>
            </material>
        </visual>
        <inertial>
            <origin xyz="-0.00781722 -1.63693e-05 0.0404875" rpy="0 0 0"/>
            <mass value="0.329199"/>
            <inertia ixx="0.000195409" ixy="-2.54474e-07" ixz="1.84257e-06" iyy="0.000240827" iyz="-5.40945e-07" izz="0.000214844"/>
        </inertial>
    </link>

    <link name="arm_right_elbow_pitch">
        <!-- Shapes for elbow_mount_2 -->
        <!-- Shapes for elbow_mount -->
        <!-- Shapes for housing_front -->
        <!-- Shapes for output_shaft_front -->
        <!-- Shapes for motor_shell -->
        <!-- Shapes for housing_rear -->
        <visual>
            <origin xyz="0 0 0" rpy="0 0 0"/>
            <geometry>
                <mesh filename="../meshes/arm_right_elbow_pitch_visual.stl"/>
            </geometry>
            <material name="arm_right_elbow_pitch_material">
                <color rgba="0.8 0.8 0.8 1.0"/>
            </material>
        </visual>
        <inertial>
            <origin xyz="-4.27603e-05 0.0715053 -0.0278824" rpy="0 0 0"/>
            <mass value="0.416078"/>
            <inertia ixx="0.000651024" ixy="-3.68022e-07" ixz="-1.28385e-07" iyy="0.000336987" iyz="-1.34653e-05" izz="0.000521369"/>
        </inertial>
    </link>

    <link name="arm_right_elbow_roll">
        <!-- Shapes for geometry_stud_lowerarm -->
        <collision>
            <origin xyz="0 0 -0.01" rpy="-3.14159 0 0"/>
            <geometry>
                <cylinder length="0.12" radius="0.03"/>
            </geometry>
        </collision>
        <visual>
            <origin xyz="0 0 0" rpy="0 0 0"/>
            <geometry>
                <mesh filename="../meshes/arm_right_elbow_roll_visual.stl"/>
            </geometry>
            <material name="arm_right_elbow_roll_material">
                <color rgba="0.8 0.8 0.8 1.0"/>
            </material>
        </visual>
        <inertial>
            <origin xyz="0 0 0.005" rpy="0 0 0"/>
            <mass value="0.000826239"/>
            <inertia ixx="1.20493e-08" ixy="0" ixz="0" iyy="1.20493e-08" iyz="0" izz="1.0328e-08"/>
        </inertial>
    </link>

    <link name="arm_right_hand_link">
        <!-- Shapes for wrist -->
        <!-- Shapes for metal_case -->
        <!-- Shapes for bottom_shell -->
        <!-- Shapes for top_shell -->
        <!-- Shapes for shaft -->
        <!-- Shapes for claw -->
        <!-- Shapes for linkage_1 -->
        <!-- Shapes for linkage_2 -->
        <!-- Shapes for base_plate -->
        <!-- Shapes for claw -->
        <!-- Shapes for linkage_1 -->
        <!-- Shapes for linkage_2 -->
        <visual>
            <origin xyz="0 0 0" rpy="0 0 0"/>
            <geometry>
                <mesh filename="../meshes/arm_right_hand_link_visual.stl"/>
            </geometry>
            <material name="arm_right_hand_link_material">
                <color rgba="0.8 0.8 0.8 1.0"/>
            </material>
        </visual>
        <inertial>
            <origin xyz="-0.00248666 0.0134979 -0.0541316" rpy="0 0 0"/>
            <mass value="0.291741"/>
            <inertia ixx="0.000556491" ixy="3.82363e-06" ixz="-2.67254e-06" iyy="0.000494025" iyz="-0.000102102" izz="0.000161723"/>
        </inertial>
    </link>

    <joint name="arm_hand_r" type="fixed">
        <origin xyz="0 0 0" rpy="-3.14159 0 -1.5708"/>
        <parent link="arm_right_elbow_roll"/>
        <child link="arm_right_hand_link"/>
        <axis xyz="0 0 1"/>
        <limit effort="20" velocity="15" />
        <joint_properties friction="0.0"/>
    </joint>

    <joint name="arm_right_elbow_roll_joint" type="revolute">
        <origin xyz="0 0.123 -0.0255" rpy="1.5708 0 -3.14159"/>
        <parent link="arm_right_elbow_pitch"/>
        <child link="arm_right_elbow_roll"/>
        <axis xyz="0 0 1"/>
        <limit effort="20" velocity="15" lower="-0.785398" upper="0.785398"/>
        <joint_properties friction="0.0"/>
    </joint>

    <joint name="arm_right_elbow_pitch_joint" type="revolute">
        <origin xyz="0.0245 0 0.043" rpy="1.5708 0 1.5708"/>
        <parent link="arm_right_shoulder_yaw"/>
        <child link="arm_right_elbow_pitch"/>
        <axis xyz="0 0 1"/>
        <limit effort="20" velocity="15" lower="-1.5708" upper="-0"/>
        <joint_properties friction="0.0"/>
    </joint>

    <joint name="arm_right_shoulder_yaw_joint" type="revolute">
        <origin xyz="0 0.123 -0.0255" rpy="1.5708 0 3.14159"/>
        <parent link="arm_right_shoulder_roll"/>
        <child link="arm_right_shoulder_yaw"/>
        <axis xyz="0 0 1"/>
        <limit effort="20" velocity="15" lower="-0.785398" upper="0.785398"/>
        <joint_properties friction="0.0"/>
    </joint>

    <joint name="arm_right_shoulder_roll_joint" type="revolute">
        <origin xyz="-0.0255 0 0.043" rpy="1.5708 -1.309 -1.5708"/>
        <parent link="arm_right_shoulder_pitch"/>
        <child link="arm_right_shoulder_roll"/>
        <axis xyz="0 0 1"/>
        <limit effort="20" velocity="15" lower="-0" upper="1.5708"/>
        <joint_properties friction="0.0"/>
    </joint>

    <joint name="arm_right_shoulder_pitch_joint" type="revolute">
        <origin xyz="0 -0.133 0.164028" rpy="-1.5708 0 -3.14159"/>
        <parent link="base"/>
        <child link="arm_right_shoulder_pitch"/>
        <axis xyz="0 0 1"/>
        <limit effort="20" velocity="15" lower="-0.785398" upper="1.5708"/>
        <joint_properties friction="0.0"/>
    </joint>

    <link name="leg_left_hip_roll">
        <!-- Shapes for upperleg_x_housing_middle -->
        <!-- Shapes for stopper_z -->
        <!-- Shapes for rear_struct -->
        <!-- Shapes for output_shaft_front -->
        <!-- Shapes for motor_shell -->
        <!-- Shapes for housing_front -->
        <!-- Shapes for housing_rear -->
        <visual>
            <origin xyz="0 0 0" rpy="0 0 0"/>
            <geometry>
                <mesh filename="../meshes/leg_left_hip_roll_visual.stl"/>
            </geometry>
            <material name="leg_left_hip_roll_material">
                <color rgba="0.8 0.8 0.8 1.0"/>
            </material>
        </visual>
        <inertial>
            <origin xyz="-0.00410941 -0.000112596 -0.0464623" rpy="0 0 0"/>
            <mass value="0.83786"/>
            <inertia ixx="0.000979918" ixy="6.45954e-06" ixz="-1.63173e-05" iyy="0.000896043" iyz="-5.43389e-06" izz="0.000727678"/>
        </inertial>
    </link>

    <link name="leg_left_hip_yaw">
        <!-- Shapes for stopper_u_r -->
        <!-- Shapes for upperleg_x_housing_middle -->
        <!-- Shapes for rear_struct -->
        <!-- Shapes for output_shaft_front -->
        <!-- Shapes for motor_shell -->
        <!-- Shapes for housing_front -->
        <!-- Shapes for housing_rear -->
        <visual>
            <origin xyz="0 0 0" rpy="0 0 0"/>
            <geometry>
                <mesh filename="../meshes/leg_left_hip_yaw_visual.stl"/>
            </geometry>
            <material name="leg_left_hip_yaw_material">
                <color rgba="0.8 0.8 0.8 1.0"/>
            </material>
        </visual>
        <inertial>
            <origin xyz="-0.00411632 -8.63203e-05 0.0463382" rpy="0 0 0"/>
            <mass value="0.837683"/>
            <inertia ixx="0.000979031" ixy="-1.13217e-06" ixz="1.96352e-05" iyy="0.000898166" iyz="-5.91541e-06" izz="0.000724287"/>
        </inertial>
    </link>

    <link name="leg_left_hip_pitch">
        <!-- Shapes for rear_struct_r -->
        <!-- Shapes for housing_middle_r -->
        <!-- Shapes for geometry_stud_upperleg -->
        <collision>
            <origin xyz="0.00597627 0.039 0.0295" rpy="1.5708 1.5708 0"/>
            <geometry>
                <cylinder length="0.13" radius="0.05"/>
            </geometry>
        </collision>
        <!-- Shapes for output_shaft_front -->
        <!-- Shapes for motor_shell -->
        <!-- Shapes for housing_front -->
        <!-- Shapes for housing_rear -->
        <visual>
            <origin xyz="0 0 0" rpy="0 0 0"/>
            <geometry>
                <mesh filename="../meshes/leg_left_hip_pitch_visual.stl"/>
            </geometry>
            <material name="leg_left_hip_pitch_material">
                <color rgba="0.8 0.8 0.8 1.0"/>
            </material>
        </visual>
        <inertial>
            <origin xyz="0.0030405 0.120388 0.0210924" rpy="0 0 0"/>
            <mass value="0.947974"/>
            <inertia ixx="0.00286449" ixy="0.00012235" ixz="-2.15676e-05" iyy="0.00102465" iyz="0.000265775" izz="0.00259958"/>
        </inertial>
    </link>

    <link name="leg_left_knee_pitch">
        <!-- Shapes for rear_struct -->
        <!-- Shapes for ankle_mount_2 -->
        <!-- Shapes for housing_front_ankle -->
        <!-- Shapes for geometry_stud_lowerleg -->
        <collision>
            <origin xyz="0 -0.115 0.022" rpy="-1.5708 1.5708 0"/>
            <geometry>
                <cylinder length="0.15" radius="0.04"/>
            </geometry>
        </collision>
        <!-- Shapes for ankle_mount -->
        <!-- Shapes for housing_front -->
        <!-- Shapes for output_shaft_front -->
        <!-- Shapes for motor_shell -->
        <!-- Shapes for housing_rear -->
        <visual>
            <origin xyz="0 0 0" rpy="0 0 0"/>
            <geometry>
                <mesh filename="../meshes/leg_left_knee_pitch_visual.stl"/>
            </geometry>
            <material name="leg_left_knee_pitch_material">
                <color rgba="0.8 0.8 0.8 1.0"/>
            </material>
        </visual>
        <inertial>
            <origin xyz="-4.09608e-05 -0.112761 0.025479" rpy="0 0 0"/>
            <mass value="0.66094"/>
            <inertia ixx="0.00232495" ixy="-4.11082e-07" ixz="1.37295e-06" iyy="0.000567475" iyz="2.97519e-05" izz="0.00206035"/>
        </inertial>
    </link>

    <link name="leg_left_ankle_pitch">
        <!-- Shapes for feet_mount_l -->
        <!-- Shapes for feet_mount_2_l -->
        <visual>
            <origin xyz="0 0 0" rpy="0 0 0"/>
            <geometry>
                <mesh filename="../meshes/leg_left_ankle_pitch_visual.stl"/>
            </geometry>
            <material name="leg_left_ankle_pitch_material">
                <color rgba="0.8 0.8 0.8 1.0"/>
            </material>
        </visual>
        <inertial>
            <origin xyz="0.0131065 0.0273743 0.0274153" rpy="0 0 0"/>
            <mass value="0.106196"/>
            <inertia ixx="0.000188241" ixy="-2.50802e-05" ixz="-7.26755e-06" iyy="0.000142962" iyz="-7.72963e-06" izz="8.17202e-05"/>
        </inertial>
    </link>

    <link name="leg_left_ankle_roll">
        <!-- Shapes for flat_foot -->
        <collision>
            <origin xyz="0 0.03 0.006" rpy="1.5708 0 0"/>
            <geometry>
                <box size="0.072 0.22 0.04"/>
            </geometry>
        </collision>
        <!-- Shapes for housing_front -->
        <!-- Shapes for output_shaft_front -->
        <!-- Shapes for motor_shell -->
        <!-- Shapes for housing_rear -->
        <visual>
            <origin xyz="0 0 0" rpy="0 0 0"/>
            <geometry>
                <mesh filename="../meshes/leg_left_ankle_roll_visual.stl"/>
            </geometry>
            <material name="leg_left_ankle_roll_material">
                <color rgba="0.8 0.8 0.8 1.0"/>
            </material>
        </visual>
        <inertial>
            <origin xyz="2.38759e-05 0.0235917 0.0199185" rpy="0 0 0"/>
            <mass value="0.678609"/>
            <inertia ixx="0.00195688" ixy="5.52089e-07" ixz="-8.37305e-07" iyy="0.00188814" iyz="0.00014531" izz="0.000576474"/>
        </inertial>
    </link>

    <joint name="leg_left_ankle_roll_joint" type="revolute">
        <origin xyz="0.03 0.05 0.025" rpy="0 1.5708 0"/>
        <parent link="leg_left_ankle_pitch"/>
        <child link="leg_left_ankle_roll"/>
        <axis xyz="0 0 1"/>
        <limit effort="20" velocity="15" lower="-0.261799" upper="0.261799"/>
        <joint_properties friction="0.0"/>
    </joint>

    <joint name="leg_left_ankle_pitch_joint" type="revolute">
        <origin xyz="0 -0.16 -0.003" rpy="0 0 -3.14159"/>
        <parent link="leg_left_knee_pitch"/>
        <child link="leg_left_ankle_pitch"/>
        <axis xyz="0 0 1"/>
        <limit effort="20" velocity="15" lower="-0.785398" upper="0.785398"/>
        <joint_properties friction="0.0"/>
    </joint>

    <joint name="leg_left_knee_pitch_joint" type="revolute">
        <origin xyz="0 0.15 -0.018" rpy="0 0 -3.14159"/>
        <parent link="leg_left_hip_pitch"/>
        <child link="leg_left_knee_pitch"/>
        <axis xyz="0 0 1"/>
        <limit effort="20" velocity="15" lower="0" upper="2.44346"/>
        <joint_properties friction="0.0"/>
    </joint>

    <joint name="leg_left_hip_pitch_joint" type="revolute">
        <origin xyz="0.027 0 0.052" rpy="1.5708 -0.785398 -1.5708"/>
        <parent link="leg_left_hip_yaw"/>
        <child link="leg_left_hip_pitch"/>
        <axis xyz="0 0 1"/>
        <limit effort="20" velocity="15" lower="-1.89805" upper="0.981748"/>
        <joint_properties friction="0.0"/>
    </joint>

    <joint name="leg_left_hip_yaw_joint" type="revolute">
        <origin xyz="0.027 0 -0.052" rpy="-1.5708 0 -1.5708"/>
        <parent link="leg_left_hip_roll"/>
        <child link="leg_left_hip_yaw"/>
        <axis xyz="0 0 1"/>
        <limit effort="20" velocity="15" lower="-0.981748" upper="0.589049"/>
        <joint_properties friction="0.0"/>
    </joint>

    <joint name="leg_left_hip_roll_joint" type="revolute">
        <origin xyz="-0.0290919 0.08 -0.057369" rpy="0 0.785398 0"/>
        <parent link="base"/>
        <child link="leg_left_hip_roll"/>
        <axis xyz="0 0 1"/>
        <limit effort="20" velocity="15" lower="-0.174533" upper="1.5708"/>
        <joint_properties friction="0.0"/>
    </joint>

    <link name="leg_right_hip_roll">
        <!-- Shapes for upperleg_x_housing_middle -->
        <!-- Shapes for stopper_z -->
        <!-- Shapes for rear_struct -->
        <!-- Shapes for output_shaft_front -->
        <!-- Shapes for motor_shell -->
        <!-- Shapes for housing_front -->
        <!-- Shapes for housing_rear -->
        <visual>
            <origin xyz="0 0 0" rpy="0 0 0"/>
            <geometry>
                <mesh filename="../meshes/leg_right_hip_roll_visual.stl"/>
            </geometry>
            <material name="leg_right_hip_roll_material">
                <color rgba="0.8 0.8 0.8 1.0"/>
            </material>
        </visual>
        <inertial>
            <origin xyz="0.00410941 -0.00018505 -0.0464478" rpy="0 0 0"/>
            <mass value="0.83786"/>
            <inertia ixx="0.000979766" ixy="-3.69135e-06" ixz="1.57667e-05" iyy="0.000896334" iyz="-4.74708e-06" izz="0.000727235"/>
        </inertial>
    </link>

    <link name="leg_right_hip_yaw">
        <!-- Shapes for upperleg_x_housing_middle -->
        <!-- Shapes for stopper_u_l -->
        <!-- Shapes for rear_struct -->
        <!-- Shapes for output_shaft_front -->
        <!-- Shapes for motor_shell -->
        <!-- Shapes for housing_front -->
        <!-- Shapes for housing_rear -->
        <visual>
            <origin xyz="0 0 0" rpy="0 0 0"/>
            <geometry>
                <mesh filename="../meshes/leg_right_hip_yaw_visual.stl"/>
            </geometry>
            <material name="leg_right_hip_yaw_material">
                <color rgba="0.8 0.8 0.8 1.0"/>
            </material>
        </visual>
        <inertial>
            <origin xyz="0.00411632 -1.3851e-05 0.0463238" rpy="0 0 0"/>
            <mass value="0.837683"/>
            <inertia ixx="0.000978901" ixy="-1.63559e-06" ixz="-1.90847e-05" iyy="0.000898454" iyz="-5.23378e-06" izz="0.000723868"/>
        </inertial>
    </link>

    <link name="leg_right_hip_pitch">
        <!-- Shapes for housing_middle_l -->
        <!-- Shapes for rear_struct_l -->
        <!-- Shapes for geometry_stud_upperleg -->
        <collision>
            <origin xyz="0.00597627 0.039 -0.0295" rpy="1.5708 1.5708 0"/>
            <geometry>
                <cylinder length="0.13" radius="0.05"/>
            </geometry>
        </collision>
        <!-- Shapes for output_shaft_front -->
        <!-- Shapes for motor_shell -->
        <!-- Shapes for housing_front -->
        <!-- Shapes for housing_rear -->
        <visual>
            <origin xyz="0 0 0" rpy="0 0 0"/>
            <geometry>
                <mesh filename="../meshes/leg_right_hip_pitch_visual.stl"/>
            </geometry>
            <material name="leg_right_hip_pitch_material">
                <color rgba="0.8 0.8 0.8 1.0"/>
            </material>
        </visual>
        <inertial>
            <origin xyz="0.00319928 0.120388 -0.0210924" rpy="0 0 0"/>
            <mass value="0.947974"/>
            <inertia ixx="0.00286448" ixy="0.000117078" ixz="2.6845e-05" iyy="0.00102371" iyz="-0.000265774" izz="0.00259864"/>
        </inertial>
    </link>

    <link name="leg_right_knee_pitch">
        <!-- Shapes for housing_front_ankle -->
        <!-- Shapes for ankle_mount -->
        <!-- Shapes for rear_struct -->
        <!-- Shapes for geometry_stud_lowerleg -->
        <collision>
            <origin xyz="0 0.115 -0.022" rpy="1.5708 1.5708 0"/>
            <geometry>
                <cylinder length="0.15" radius="0.04"/>
            </geometry>
        </collision>
        <!-- Shapes for ankle_mount_2 -->
        <!-- Shapes for housing_front -->
        <!-- Shapes for output_shaft_front -->
        <!-- Shapes for motor_shell -->
        <!-- Shapes for housing_rear -->
        <visual>
            <origin xyz="0 0 0" rpy="0 0 0"/>
            <geometry>
                <mesh filename="../meshes/leg_right_knee_pitch_visual.stl"/>
            </geometry>
            <material name="leg_right_knee_pitch_material">
                <color rgba="0.8 0.8 0.8 1.0"/>
            </material>
        </visual>
        <inertial>
            <origin xyz="-5.03974e-05 0.112761 -0.025479" rpy="0 0 0"/>
            <mass value="0.66094"/>
            <inertia ixx="0.00232495" ixy="1.33233e-06" ixz="-1.18694e-06" iyy="0.000567474" iyz="2.97519e-05" izz="0.00206035"/>
        </inertial>
    </link>

    <link name="leg_right_ankle_pitch">
        <!-- Shapes for feet_mount_2_r -->
        <!-- Shapes for feet_mount_r -->
        <visual>
            <origin xyz="0 0 0" rpy="0 0 0"/>
            <geometry>
                <mesh filename="../meshes/leg_right_ankle_pitch_visual.stl"/>
            </geometry>
            <material name="leg_right_ankle_pitch_material">
                <color rgba="0.8 0.8 0.8 1.0"/>
            </material>
        </visual>
        <inertial>
            <origin xyz="0.0131065 0.0273743 -0.0274153" rpy="0 0 0"/>
            <mass value="0.106196"/>
            <inertia ixx="0.000188241" ixy="-2.50802e-05" ixz="7.26754e-06" iyy="0.000142962" iyz="7.72962e-06" izz="8.17203e-05"/>
        </inertial>
    </link>

    <link name="leg_right_ankle_roll">
        <!-- Shapes for flat_foot -->
        <collision>
            <origin xyz="0 0.03 0.006" rpy="1.5708 0 0"/>
            <geometry>
                <box size="0.072 0.22 0.04"/>
            </geometry>
        </collision>
        <!-- Shapes for housing_front -->
        <!-- Shapes for output_shaft_front -->
        <!-- Shapes for motor_shell -->
        <!-- Shapes for housing_rear -->
        <visual>
            <origin xyz="0 0 0" rpy="0 0 0"/>
            <geometry>
                <mesh filename="../meshes/leg_right_ankle_roll_visual.stl"/>
            </geometry>
            <material name="leg_right_ankle_roll_material">
                <color rgba="0.8 0.8 0.8 1.0"/>
            </material>
        </visual>
        <inertial>
            <origin xyz="2.38759e-05 0.0235917 0.0199185" rpy="0 0 0"/>
            <mass value="0.678609"/>
            <inertia ixx="0.00195688" ixy="5.52089e-07" ixz="-8.37305e-07" iyy="0.00188814" iyz="0.00014531" izz="0.000576474"/>
        </inertial>
    </link>

    <joint name="leg_right_ankle_roll_joint" type="revolute">
        <origin xyz="0.03 0.05 -0.025" rpy="0 1.5708 0"/>
        <parent link="leg_right_ankle_pitch"/>
        <child link="leg_right_ankle_roll"/>
        <axis xyz="0 0 1"/>
        <limit effort="20" velocity="15" lower="-0.261799" upper="0.261799"/>
        <joint_properties friction="0.0"/>
    </joint>

    <joint name="leg_right_ankle_pitch_joint" type="revolute">
        <origin xyz="0 0.16 0.003" rpy="0 0 0"/>
        <parent link="leg_right_knee_pitch"/>
        <child link="leg_right_ankle_pitch"/>
        <axis xyz="0 0 1"/>
        <limit effort="20" velocity="15" lower="-0.785398" upper="0.785398"/>
        <joint_properties friction="0.0"/>
    </joint>

    <joint name="leg_right_knee_pitch_joint" type="revolute">
        <origin xyz="0 0.15 0.018" rpy="0 0 0"/>
        <parent link="leg_right_hip_pitch"/>
        <child link="leg_right_knee_pitch"/>
        <axis xyz="0 0 1"/>
        <limit effort="20" velocity="15" lower="-0" upper="2.44346"/>
        <joint_properties friction="0.0"/>
    </joint>

    <joint name="leg_right_hip_pitch_joint" type="revolute">
        <origin xyz="-0.027 0 0.052" rpy="1.5708 -0.785398 -1.5708"/>
        <parent link="leg_right_hip_yaw"/>
        <child link="leg_right_hip_pitch"/>
        <axis xyz="0 0 1"/>
        <limit effort="20" velocity="15" lower="-1.89805" upper="0.981748"/>
        <joint_properties friction="0.0"/>
    </joint>

    <joint name="leg_right_hip_yaw_joint" type="revolute">
        <origin xyz="-0.027 0 -0.052" rpy="-1.5708 0 1.5708"/>
        <parent link="leg_right_hip_roll"/>
        <child link="leg_right_hip_yaw"/>
        <axis xyz="0 0 1"/>
        <limit effort="20" velocity="15" lower="-0.589049" upper="0.981748"/>
        <joint_properties friction="0.0"/>
    </joint>

    <joint name="leg_right_hip_roll_joint" type="revolute">
        <origin xyz="-0.0290919 -0.08 -0.057369" rpy="0 -0.785398 3.14159"/>
        <parent link="base"/>
        <child link="leg_right_hip_roll"/>
        <axis xyz="0 0 1"/>
        <limit effort="20" velocity="15" lower="-1.5708" upper="0.174533"/>
        <joint_properties friction="0.0"/>
    </joint>

</robot>
